Workbook

Sheet Assessment
A1: Clinical Trial Complexity Assessment
A2: Go / No-Go Decision Support · 5 Dimensions · 37 Criteria · OPAL / EFACCT Framework
A3: Study Name:
A4: Protocol #:
A5: Assessment Date:
A6: Assessor:
A7: ID | B7: Criterion | C7: Score (0–3) | D7: Score Description | E7: Wtd. Contrib.
A8: DIMENSION 1: PROTOCOL DESIGN & STUDY COMPLEXITY (weight ×1.2 | max raw 21 | red flag if raw > 15)
A9: 1.1 | B9: Trial Phase | D9: =IFERROR(INDEX(Lookup!$B$2:$E$38,MATCH(A9,Lookup!$A$2:$A$38,0),C9+1),"") | E9: =IF(ISNUMBER(C9),C9*1.2,0)
A10: 1.2 | B10: Study Design Complexity | D10: =IFERROR(INDEX(Lookup!$B$2:$E$38,MATCH(A10,Lookup!$A$2:$A$38,0),C10+1),"") | E10: =IF(ISNUMBER(C10),C10*1.2,0)
A11: 1.3 | B11: Number of Treatment Arms | D11: =IFERROR(INDEX(Lookup!$B$2:$E$38,MATCH(A11,Lookup!$A$2:$A$38,0),C11+1),"") | E11: =IF(ISNUMBER(C11),C11*1.2,0)
A12: 1.4 | B12: Eligibility Criteria Complexity | D12: =IFERROR(INDEX(Lookup!$B$2:$E$38,MATCH(A12,Lookup!$A$2:$A$38,0),C12+1),"") | E12: =IF(ISNUMBER(C12),C12*1.2,0)
A13: 1.5 | B13: Biomarker Requirements | D13: =IFERROR(INDEX(Lookup!$B$2:$E$38,MATCH(A13,Lookup!$A$2:$A$38,0),C13+1),"") | E13: =IF(ISNUMBER(C13),C13*1.2,0)
A14: 1.6 | B14: Primary Endpoint Complexity | D14: =IFERROR(INDEX(Lookup!$B$2:$E$38,MATCH(A14,Lookup!$A$2:$A$38,0),C14+1),"") | E14: =IF(ISNUMBER(C14),C14*1.2,0)
A15: 1.7 | B15: Protocol Amendment History | D15: =IFERROR(INDEX(Lookup!$B$2:$E$38,MATCH(A15,Lookup!$A$2:$A$38,0),C15+1),"") | E15: =IF(ISNUMBER(C15),C15*1.2,0)
A16: D1 | B16: Dimension 1 Subtotal | C16: =SUM(C9:C15) | D16: =C16&" / 21 raw (⚑ RED FLAG if > 15)" | E16: =SUM(E9:E15)
A18: DIMENSION 2: OPERATIONAL EXECUTION & SITE BURDEN (weight ×1.5 | max raw 24 | red flag if raw > 17)
A19: 2.1 | B19: Number of Study Visits | D19: =IFERROR(INDEX(Lookup!$B$2:$E$38,MATCH(A19,Lookup!$A$2:$A$38,0),C19+1),"") | E19: =IF(ISNUMBER(C19),C19*1.5,0)
A20: 2.2 | B20: Visit Duration | D20: =IFERROR(INDEX(Lookup!$B$2:$E$38,MATCH(A20,Lookup!$A$2:$A$38,0),C20+1),"") | E20: =IF(ISNUMBER(C20),C20*1.5,0)
A21: 2.3 | B21: Assessment Procedures | D21: =IFERROR(INDEX(Lookup!$B$2:$E$38,MATCH(A21,Lookup!$A$2:$A$38,0),C21+1),"") | E21: =IF(ISNUMBER(C21),C21*1.5,0)
A22: 2.4 | B22: Data Collection Burden | D22: =IFERROR(INDEX(Lookup!$B$2:$E$38,MATCH(A22,Lookup!$A$2:$A$38,0),C22+1),"") | E22: =IF(ISNUMBER(C22),C22*1.5,0)
A23: 2.5 | B23: Monitoring Intensity | D23: =IFERROR(INDEX(Lookup!$B$2:$E$38,MATCH(A23,Lookup!$A$2:$A$38,0),C23+1),"") | E23: =IF(ISNUMBER(C23),C23*1.5,0)
A24: 2.6 | B24: Investigational Product Handling | D24: =IFERROR(INDEX(Lookup!$B$2:$E$38,MATCH(A24,Lookup!$A$2:$A$38,0),C24+1),"") | E24: =IF(ISNUMBER(C24),C24*1.5,0)
A25: 2.7 | B25: Third-Party Coordination | D25: =IFERROR(INDEX(Lookup!$B$2:$E$38,MATCH(A25,Lookup!$A$2:$A$38,0),C25+1),"") | E25: =IF(ISNUMBER(C25),C25*1.5,0)
A26: 2.8 | B26: Safety Reporting Requirements | D26: =IFERROR(INDEX(Lookup!$B$2:$E$38,MATCH(A26,Lookup!$A$2:$A$38,0),C26+1),"") | E26: =IF(ISNUMBER(C26),C26*1.5,0)
A27: 2.9 | B27: Unscheduled / Event-Driven Visit Burden | D27: =IFERROR(INDEX(Lookup!$B$2:$E$38,MATCH(A27,Lookup!$A$2:$A$38,0),C27+1),"") | E27: =IF(ISNUMBER(C27),C27*1.5,0)
A28: D2 | B28: Dimension 2 Subtotal | C28: =SUM(C19:C27) | D28: =C28&" / 27 raw (⚑ RED FLAG if > 19)" | E28: =SUM(E19:E27)
A30: DIMENSION 3: REGULATORY & OVERSIGHT REQUIREMENTS (weight ×1.0 | max raw 18 | red flag if raw > 13)
A31: 3.1 | B31: IRB / Ethics Review | D31: =IFERROR(INDEX(Lookup!$B$2:$E$38,MATCH(A31,Lookup!$A$2:$A$38,0),C31+1),"") | E31: =IF(ISNUMBER(C31),C31*1.0,0)
A32: 3.2 | B32: Regulatory Submissions | D32: =IFERROR(INDEX(Lookup!$B$2:$E$38,MATCH(A32,Lookup!$A$2:$A$38,0),C32+1),"") | E32: =IF(ISNUMBER(C32),C32*1.0,0)
A33: 3.3 | B33: Informed Consent Complexity | D33: =IFERROR(INDEX(Lookup!$B$2:$E$38,MATCH(A33,Lookup!$A$2:$A$38,0),C33+1),"") | E33: =IF(ISNUMBER(C33),C33*1.0,0)
A34: 3.4 | B34: Data Privacy Requirements | D34: =IFERROR(INDEX(Lookup!$B$2:$E$38,MATCH(A34,Lookup!$A$2:$A$38,0),C34+1),"") | E34: =IF(ISNUMBER(C34),C34*1.0,0)
A35: 3.5 | B35: Oversight Committees | D35: =IFERROR(INDEX(Lookup!$B$2:$E$38,MATCH(A35,Lookup!$A$2:$A$38,0),C35+1),"") | E35: =IF(ISNUMBER(C35),C35*1.0,0)
A36: 3.6 | B36: Audit / Inspection Risk | D36: =IFERROR(INDEX(Lookup!$B$2:$E$38,MATCH(A36,Lookup!$A$2:$A$38,0),C36+1),"") | E36: =IF(ISNUMBER(C36),C36*1.0,0)
A37: D3 | B37: Dimension 3 Subtotal | C37: =SUM(C31:C36) | D37: =C37&" / 18 raw (⚑ RED FLAG if > 13)" | E37: =SUM(E31:E36)
A39: DIMENSION 4: RESOURCE & WORKFORCE CAPACITY (weight ×1.3 | max raw 21 | red flag if raw > 15)
A40: 4.1 | B40: Coordinator Time Required | D40: =IFERROR(INDEX(Lookup!$B$2:$E$38,MATCH(A40,Lookup!$A$2:$A$38,0),C40+1),"") | E40: =IF(ISNUMBER(C40),C40*1.3,0)
A41: 4.2 | B41: Specialized Expertise Needed | D41: =IFERROR(INDEX(Lookup!$B$2:$E$38,MATCH(A41,Lookup!$A$2:$A$38,0),C41+1),"") | E41: =IF(ISNUMBER(C41),C41*1.3,0)
A42: 4.3 | B42: Space & Equipment Requirements | D42: =IFERROR(INDEX(Lookup!$B$2:$E$38,MATCH(A42,Lookup!$A$2:$A$38,0),C42+1),"") | E42: =IF(ISNUMBER(C42),C42*1.3,0)
A43: 4.4 | B43: Pharmacy Resources | D43: =IFERROR(INDEX(Lookup!$B$2:$E$38,MATCH(A43,Lookup!$A$2:$A$38,0),C43+1),"") | E43: =IF(ISNUMBER(C43),C43*1.3,0)
...

Sheet Dashboard
A1: ASSESSMENT DASHBOARD
A2: Clinical Trial Complexity Assessment — Go / No-Go Decision Support
A4: OVERALL SCORE SUMMARY
B5: Overall Score | D5: Complexity Band | F5: Decision
B6: =Assessment!C62 | D6: =Assessment!C63 | F6: =Assessment!C65
B7: =Assessment!C66
A9: DIMENSION SCORES
B10: Dimension | C10: Raw Score | D10: Max Raw | E10: % Score | F10: Wt. Score | G10: Red Flag?
B11: Dim 1: Protocol Design & Study Complexity | C11: =Assessment!C16 | D11: 21 | E11: =IFERROR(ROUND(C11/D11*100,0),0) | F11: =Assessment!E16 | G11: =IF(Assessment!C16>15,"⚑ FLAG","✓ OK")
B12: Dim 2: Operational Execution & Site Burden | C12: =Assessment!C28 | D12: 27 | E12: =IFERROR(ROUND(C12/D12*100,0),0) | F12: =Assessment!E28 | G12: =IF(Assessment!C28>19,"⚑ FLAG","✓ OK")
B13: Dim 3: Regulatory & Oversight Requirements | C13: =Assessment!C37 | D13: 18 | E13: =IFERROR(ROUND(C13/D13*100,0),0) | F13: =Assessment!E37 | G13: =IF(Assessment!C37>13,"⚑ FLAG","✓ OK")
B14: Dim 4: Resource & Workforce Capacity | C14: =Assessment!C49 | D14: 27 | E14: =IFERROR(ROUND(C14/D14*100,0),0) | F14: =Assessment!E49 | G14: =IF(Assessment!C49>19,"⚑ FLAG","✓ OK")
B15: Dim 5: Patient Population & Recruitment | C15: =Assessment!C58 | D15: 18 | E15: =IFERROR(ROUND(C15/D15*100,0),0) | F15: =Assessment!E58 | G15: =IF(Assessment!C58>13,"⚑ FLAG","✓ OK")
A34: DECISION MATRIX
A35: Overall Score | B35: Dim 5 Raw | C35: Decision | D35: Rationale
A36: 0–40 | B36: 0–6 | C36: GO | D36: Standard activation — proceed with normal planning
A37: 0–40 | B37: 7–12 | C37: GO with Monitoring | D37: Proceed with enhanced recruitment planning
A38: 0–40 | B38: 13–18 | C38: CONDITIONAL GO | D38: Robust recruitment mitigation plan required
A39: 41–65 | B39: 0–6 | C39: GO with Planning | D39: Resource allocation and risk mitigation plan required
A40: 41–65 | B40: 7–12 | C40: CONDITIONAL GO | D40: Adequate resources and strategy must be confirmed
A41: 41–65 | B41: 13–18 | C41: NO-GO | D41: Decline unless exceptional strategic value exists
A42: 66–100 | B42: 0–6 | C42: CONDITIONAL GO | D42: Exceptional justification and comprehensive plan required
A43: 66–100 | B43: 7–12 | C43: NO-GO | D43: Decline unless transformational strategic opportunity
A44: 66–100 | B44: 13–18 | C44: NO-GO | D44: Decline — risk of failure is too high

Sheet Lookup
A1: Item ID | B1: Score 0 (Low) | C1: Score 1 | D1: Score 2 | E1: Score 3 (High)
A2: 1.1 | B2: Phase IV / Observational | C2: Phase III | D2: Phase II | E2: Phase I / First-in-Human
A3: 1.2 | B3: Simple parallel / observational | C3: Crossover / factorial | D3: Adaptive randomization / dose-finding | E3: Complex adaptive with multiple decision points
A4: 1.3 | B4: Single / observational | C4: Two arms | D4: Three arms | E4: Four or more arms
A5: 1.4 | B5: Broad (≤10 criteria) | C5: Moderate (11–20 criteria) | D5: Restrictive (21–30 criteria) | E5: Highly restrictive (>30 or specialized testing required)
A6: 1.5 | B6: None required | C6: Standard routine laboratory | D6: Specialized send-out testing | E6: Multiple specialized / novel assays
A7: 1.6 | B7: Simple clinical or survival endpoint | C7: Patient-reported outcome (PRO) / QoL | D7: Composite or imaging endpoint | E7: Novel endpoint / central adjudication required
A8: 1.7 | B8: Stable — no amendments anticipated | C8: 1–2 minor amendments | D8: 3–4 moderate amendments | E8: >4 amendments or major design changes
A9: 2.1 | B9: ≤5 visits | C9: 6–10 visits | D9: 11–20 visits | E9: >20 visits
A10: 2.2 | B10: <1 hour — routine visit | C10: 1–2 hours — standard procedures | D10: 2–4 hours — multiple procedures | E10: >4 hours — complex / inpatient
A11: 2.3 | B11: Routine vitals and labs | C11: Standard imaging or functional tests | D11: Specialized procedures (PK, imaging) | E11: Multiple specialized / invasive procedures
A12: 2.4 | B12: Simple eCRF — minimal fields | C12: Standard eCRF — moderate fields | D12: Complex eCRF — extensive data points | E12: Multiple systems / real-time / PRO support required
... A38: 4.9 | B38: Routine visits — labs, questionnaires, standard imaging | C38: Extended visits or minor procedures — infusion, serial PK sampling | D38: Invasive or multi-hour procedures — biopsy, apheresis, sedation, telemetry | E38: Multi-day inpatient or chained procedures — mobilization + apheresis, conditioning
